Workbook

Sheet 1-参数配置
A1: Robovan商业模式分析 - 参数配置表（动态模型）
A2: 生成日期：2025-11-12 12:33:09
A3: ⭐ 黄色单元格可直接修改，其他Sheet会自动更新计算结果！
A5: 【A区】车辆基本参数
A6: 参数项 | B6: 无人车 | C6: 人驾电动轻卡 | D6: 单位 | E6: 说明
A7: 车型 | B7: 九识Z8长续航版 | C7: 远程星享V6E/福田智蓝 | D7: - | E7: 市场主流车型
A8: 运力 | B8: 8 | C8: 7 | D8: m³ | E8: 官方参数
A9: 车辆采购成本 | B9: 79800 | C9: 145000 | D9: 元 | E9: 官网价格
A10: 电池容量 | B10: 46 | C10: 35.2 | D10: kWh | E10: 官方参数
A11: 续航里程 | B11: 260 | C11: 260 | D11: km | E11: CLTC工况
A12: 生命周期 | B12: 5 | C12: 7 | D12: 年 | E12: 技术迭代快5年；传统车7年
A13: 残值 | B13: 30000 | C13: 22000 | D13: 元 | E13: 约购车成本38%/15%
A15: 【B区】运营时间参数
A16: 参数项 | B16: 无人车 | C16: 人驾电动轻卡 | D16: 单位 | E16: 说明
A17: 年运营天数 | B17: 350 | C17: 330 | D17: 天 | E17: 少维护vs法定假日
A18: 日有效运营时长 | B18: 10 | C18: 8 | D18: 小时 | E18: 夜间受限vs8小时工作制
A19: 平均运营时速 | B19: 25 | C19: 28 | D19: km/h | E19: 保守驾驶vs经验丰富
A21: 【C区】年度成本参数
A22: 成本项 | B22: 无人车 | C22: 人驾电动轻卡 | D22: 单位 | E22: 说明
A23: 人力成本 | B23: 1000 | C23: 110000 | D23: 元/年 | E23: 1:100分摊 vs 司机+社保
A24: 软件订阅费 | B24: 34000 | C24: 0 | D24: 元/年 | E24: 8500元/季度×4
A25: 保险费用 | B25: 9000 | C25: 12000 | D25: 元/年 | E25: 风险低vs营运险
A26: 维保成本 | B26: 8000 | C26: 7000 | D26: 元/年 | E26: 传感器贵vs保养成熟
A27: 其他成本 | B27: 3000 | C27: 5000 | D27: 元/年 | E27: 停车、过路费等
A29: 【D区】能源参数
A30: 参数项 | B30: 无人车 | C30: 人驾电动轻卡 | D30: 单位 | E30: 说明
A31: 百公里电耗 | B31: 17.7 | C31: 15 | D31: kWh | E31: 传感器耗电vs行业参考
A32: 电价标准 | B32: 0.8 | C32: 0.8 | D32: 元/kWh | E32: 工业用电峰谷混合
A34: 【E区】业务场景参数
A35: 单次往返里程 | B35: 50 | C35: 公里 | D35: 仓储物流场景
A36: 单次满载件数 | B36: 500 | C36: 件 | D36: 8m³标准包裹
A38: 【F区】市场定价参数（⚠️ 外部市场价，非成本！）
A39: 按公里收费 | B39: 4.5 | C39: 元/km | D39: 短途货运市场价
A40: 按件收费 | B40: 0.3 | C40: 元/件 | D40: 城市配送标准

Sheet 2-无人车TCO
A1: 无人车模式 - 5年TCO分析（动态模型）
A2: 💡 本Sheet所有数据自动计算，修改参数表即可更新
A4: 一、一次性投资
A5: 车辆采购成本 | B5: ='1-参数配置'!B9 | C5: 元
A7: 二、运营指标（自动计算）
A8: 日均行驶里程 | B8: ='1-参数配置'!B18*'1-参数配置'!B19 | C8: km/天
A9: 年行驶里程 | B9: =B8*'1-参数配置'!B17 | C9: km/年
A10: 5年总里程 | B10: =B9*'1-参数配置'!B12 | C10: km
A11: 每公里电费 | B11: ='1-参数配置'!B31/100*'1-参数配置'!B32 | C11: 元/km
A13: 三、年度成本结构
A14: 【固定成本】
A15: 人力成本 | B15: ='1-参数配置'!B23 | C15: 元/年
A16: 软件订阅费 | B16: ='1-参数配置'!B24 | C16: 元/年
A17: 保险费用 | B17: ='1-参数配置'!B25 | C17: 元/年
A18: 固定成本小计 | B18: =SUM(B15:B17) | C18: 元/年
A20: 【可变成本】
A21: 能源成本 | B21: =B9*B11 | C21: 元/年
A22: 维保成本 | B22: ='1-参数配置'!B26 | C22: 元/年
A23: 其他成本 | B23: ='1-参数配置'!B27 | C23: 元/年
A24: 可变成本小计 | B24: =SUM(B21:B23) | C24: 元/年
A26: 年度总成本 | B26: =B18+B24 | C26: 元/年
A28: 四、5年总拥有成本(TCO)
A29: 5年固定成本 | B29: =B18*'1-参数配置'!B12 | C29: 元
A30: 5年可变成本 | B30: =B24*'1-参数配置'!B12 | C30: 元
A31: 车辆采购成本 | B31: ='1-参数配置'!B9 | C31: 元
A32: 减：残值 | B32: =-'1-参数配置'!B13 | C32: 元
A33: 净车辆成本 | B33: =B31+B32 | C33: 元
A35: 5年TCO总成本 | B35: =B29+B30+B33 | C35: 元
A37: 五、业务量指标（5年）
A38: 总里程 | B38: =B10 | C38: 公里
A39: 总时长 | B39: ='1-参数配置'!B18*'1-参数配置'!B17*'1-参数配置'!B12 | C39: 小时
A40: 总趟次 | B40: =B10/'1-参数配置'!B36 | C40: 趟
A41: 总件数 | B41: =B40*'1-参数配置'!B37 | C41: 件
A43: 六、单位成本拆解（⚠️ 成本，非收费）
A44: 每公里成本 | B44: =B35/B10 | C44: 元/km
A45: 每小时成本 | B45: =B35/B39 | C45: 元/h
A46: 每趟次成本 | B46: =B35/B40 | C46: 元/趟
A47: 每件成本 | B47: =B35/B41 | C47: 元/件
A49: 每天成本 | B49: =B35/('1-参数配置'!B17*'1-参数配置'!B12) | C49: 元/天
A50: 每月成本 | B50: =B35/('1-参数配置'!B12*12) | C50: 元/月
...

Sheet 3-人驾轻卡TCO
A1: 人驾电动轻卡模式 - 5年TCO分析（动态模型）
A2: 💡 本Sheet所有数据自动计算，修改参数表即可更新
A3: 注：实际生命周期7年，为对比统一按5年计算
A5: 一、一次性投资
A6: 车辆采购成本 | B6: ='1-参数配置'!C9 | C6: 元
A8: 二、运营指标（自动计算）
A9: 日均行驶里程 | B9: ='1-参数配置'!C18*'1-参数配置'!C19 | C9: km/天
A10: 年行驶里程 | B10: =B9*'1-参数配置'!C17 | C10: km/年
A11: 5年总里程 | B11: =B10*5 | C11: km
A12: 每公里电费 | B12: ='1-参数配置'!C31/100*'1-参数配置'!C32 | C12: 元/km
A14: 三、年度成本结构
A15: 【固定成本】
A16: 人力成本 | B16: ='1-参数配置'!C23 | C16: 元/年 ⭐
A17: 保险费用 | B17: ='1-参数配置'!C25 | C17: 元/年
A18: 固定成本小计 | B18: =SUM(B16:B17) | C18: 元/年
A20: 【可变成本】
A21: 能源成本 | B21: =B10*B12 | C21: 元/年
A22: 维保成本 | B22: ='1-参数配置'!C26 | C22: 元/年
A23: 其他成本 | B23: ='1-参数配置'!C27 | C23: 元/年
A24: 可变成本小计 | B24: =SUM(B21:B23) | C24: 元/年
A26: 年度总成本 | B26: =B18+B24 | C26: 元/年
A28: 四、5年总拥有成本(TCO)
A29: 5年固定成本 | B29: =B18*5 | C29: 元
A30: 5年可变成本 | B30: =B24*5 | C30: 元
A31: 车辆采购成本 | B31: ='1-参数配置'!C9 | C31: 元
A32: 减：残值 | B32: =-'1-参数配置'!C13 | C32: 元
A33: 净车辆成本 | B33: =B31+B32 | C33: 元
A35: 5年TCO总成本 | B35: =B29+B30+B33 | C35: 元
A37: 五、业务量指标（5年）
A38: 总里程 | B38: =B11 | C38: 公里
A39: 总时长 | B39: ='1-参数配置'!C18*'1-参数配置'!C17*5 | C39: 小时
A40: 总趟次 | B40: =B11/'1-参数配置'!C36 | C40: 趟
A41: 总件数 | B41: =B40*'1-参数配置'!C37 | C41: 件
A43: 六、单位成本拆解（⚠️ 成本，非收费）
A44: 每公里成本 | B44: =B35/B11 | C44: 元/km
A45: 每小时成本 | B45: =B35/B39 | C45: 元/h
A46: 每趟次成本 | B46: =B35/B40 | C46: 元/趟
A47: 每件成本 | B47: =B35/B41 | C47: 元/件
A49: 每天成本 | B49: =B35/('1-参数配置'!C17*5) | C49: 元/天
A50: 每月成本 | B50: =B35/60 | C50: 元/月
...

Sheet 4-成本对比
A1: 无人车 vs 人驾轻卡：成本对比分析（动态模型）
A2: 💡 本Sheet所有对比自动计算，修改参数表即可更新
A4: 一、初始投资对比
A5: 项目 | B5: 无人车 | C5: 人驾轻卡 | D5: 绝对差异 | E5: 相对差异
A6: 采购成本 | B6: ='1-参数配置'!B9 | C6: ='1-参数配置'!C9 | D6: =B6-C6 | E6: =(B6-C6)/C6
A8: 二、5年TCO对比（核心）
A9: 项目 | B9: 无人车 | C9: 人驾轻卡 | D9: 绝对差异 | E9: 相对差异
A10: 5年TCO总成本 | B10: ='2-无人车TCO'!B35 | C10: ='3-人驾轻卡TCO'!B35 | D10: =B10-C10 | E10: =(B10-C10)/C10 | F10: ⭐⭐⭐
A12: 三、单位成本对比
A13: 项目 | B13: 无人车 | C13: 人驾轻卡 | D13: 绝对差异 | E13: 相对差异
A14: 每公里成本 | B14: ='2-无人车TCO'!B35/'2-无人车TCO'!B10 | C14: ='3-人驾轻卡TCO'!B35/'3-人驾轻卡TCO'!B11 | D14: =B14-C14 | E14: =(B14-C14)/C14 | F14: ⭐
A15: 每件成本 | B15: ='2-无人车TCO'!B35/'2-无人车TCO'!B41 | C15: ='3-人驾轻卡TCO'!B35/'3-人驾轻卡TCO'!B41 | D15: =B15-C15 | E15: =(B15-C15)/C15 | F15: ⭐
A17: 四、运营效率对比
A18: 项目 | B18: 无人车 | C18: 人驾轻卡 | D18: 绝对差异 | E18: 相对差异
A19: 年运营天数 | B19: ='1-参数配置'!B17 | C19: ='1-参数配置'!C17 | D19: =B19-C19 | E19: =(B19-C19)/C19
A20: 日运营时长 | B20: ='1-参数配置'!B18 | C20: ='1-参数配置'!C18 | D20: =B20-C20 | E20: =(B20-C20)/C20
A21: 日均里程 | B21: ='2-无人车TCO'!B8 | C21: ='3-人驾轻卡TCO'!B9 | D21: =B21-C21 | E21: =(B21-C21)/C21
A22: 5年总里程 | B22: ='2-无人车TCO'!B10 | C22: ='3-人驾轻卡TCO'!B11 | D22: =B22-C22 | E22: =(B22-C22)/C22
