Workbook

Sheet 1-参数配置
A1: Robovan商业模式分析 v3.0 - 参数配置（双视角动态模型）
A2: 生成日期：2025-11-12 13:50:08
A3: ⭐ 黄色单元格可修改，绿色单元格自动计算，其他Sheet会实时更新！
A4: 📊 v3.0新增：厂商视角分析、一次性买断模式、规模化成本模型
A6: 【A区】车辆基本参数
A7: 参数项 | B7: 无人车(订阅) | C7: 人驾电动轻卡 | D7: 单位 | E7: 说明 | F7: 备注
A8: 车型 | B8: 九识Z8长续航版 | C8: 远程星享V6E/福田智蓝 | D8: - | E8: 市场主流车型
A9: 运力 | B9: 8 | C9: 7 | D9: m³ | E9: 官方参数
A10: 车辆采购成本 | B10: 79800 | C10: 145000 | D10: 元 | E10: 官网价格
A11: 电池容量 | B11: 46 | C11: 35.2 | D11: kWh | E11: 官方参数
A12: 续航里程 | B12: 260 | C12: 260 | D12: km | E12: CLTC工况
A13: 生命周期 | B13: 6 | C13: 7 | D13: 年 | E13: 无人车6年/人驾7年
A14: 残值 | B14: 30000 | C14: 22000 | D14: 元 | E14: 约购车成本38%/15%
A16: 【B区】运营参数
A17: 参数项 | B17: 无人车(订阅) | C17: 人驾电动轻卡 | D17: 单位 | E17: 说明 | F17: 备注
A18: 年运营天数 | B18: 350 | C18: 330 | D18: 天 | E18: 无人车350天/人驾330天
A19: 日有效运营时长 | B19: 10 | C19: 8 | D19: 小时 | E19: 无人车10h/人驾8h
A20: 平均运营时速 | B20: 25 | C20: 28 | D20: km/h | E20: 无人车25/人驾28
A22: 百公里电耗 | B22: 17.7 | C22: 15 | D22: kWh | E22: 无人车含传感器耗电
A23: 电价 | B23: 0.8 | C23: 0.8 | D23: 元/kWh | E23: 工业用电峰谷混合价
A25: 单次往返里程 | B25: 50 | C25: 50 | D25: km | E25: 仓库到配送中心
A26: 单次满载件数 | B26: 500 | C26: 500 | D26: 件 | E26: 标准包裹数量
A28: 市场定价(公里) | B28: 4.5 | C28: 4.5 | D28: 元/km | E28: 外部市场价格
A29: 市场定价(件) | B29: 0.3 | C29: 0.3 | D29: 元/件 | E29: 外部市场价格
A31: 【C区】运营商年度成本
A32: 参数项 | B32: 无人车(订阅) | C32: 人驾电动轻卡 | D32: 单位 | E32: 说明 | F32: 备注
A33: 人力成本 | B33: 1000 | C33: 110000 | D33: 元 | E33: 远程监控/司机工资
A34: 软件订阅费 | B34: 34000 | C34: 0 | D34: 元 | E34: 自动驾驶系统订阅
A35: 保险费用 | B35: 9000 | C35: 12000 | D35: 元 | E35: 交强险+商业险
A36: 维保成本 | B36: 8000 | C36: 7000 | D36: 元 | E36: 维修保养费用
A37: 其他成本 | B37: 3000 | C37: 5000 | D37: 元 | E37: 停车/杂费
A39: 【D区】厂商成本参数（规模驱动）
A40: 参数项 | B40: 数值 | C40: 单位 | D40: 说明
A41: ★销售规模 | B41: 1000 | C41: 台 | D41: ⭐关键参数：影响研发分摊和监控成本
A42: 固定研发投入 | B42: 380000000 | C42: 元 | D42: 平台、算法等基础研发
A43: 单车边际研发 | B43: 3000 | C43: 元 | D43: 场景适配成本
A44: 总研发投入 | B44: =B53+B54*B52 | C44: 元 | D44: =固定研发+单车边际×规模
A45: 单车研发分摊 | B45: =B55/B52 | C45: 元 | D45: =总研发÷销售规模（规模效应关键）
A47: 硬件BOM成本 | B47: 40000 | C47: 元 | D47: 激光雷达+传感器+车体
A48: 生产制造成本 | B48: 10000 | C48: 元 | D48: 组装+测试+质检
...

Sheet 2-运营商-订阅模式
A1: 运营商视角 - 无人车订阅模式TCO分析（6年）
A2: 💡 本Sheet所有数据自动计算，修改参数表即可更新
A4: 一、年度成本拆解
A5: 成本项 | B5: 金额 | C5: 单位 | D5: 计算说明
A6: 人力成本 | B6: ='1-参数配置'!B43 | C6: 元/年 | D6: 远程监控分摊
A7: 软件订阅费 | B7: ='1-参数配置'!B44 | C7: 元/年 | D7: 自动驾驶系统年费
A8: 保险费用 | B8: ='1-参数配置'!B45 | C8: 元/年 | D8: 交强+商业险
A9: 维保成本 | B9: ='1-参数配置'!B46 | C9: 元/年 | D9: 维修保养
A10: 其他成本 | B10: ='1-参数配置'!B47 | C10: 元/年 | D10: 停车/杂费
A11: 年度总成本 | B11: =SUM(B6:B10) | C11: 元/年 | D11: 运营成本合计
A13: 二、6年总拥有成本(TCO)
A14: 车辆采购成本 | B14: ='1-参数配置'!B9 | C14: 元 | D14: 一次性投入
A15: 6年运营成本 | B15: ='2-运营商-订阅模式'!B11*'1-参数配置'!B12 | C15: 元 | D15: =年成本×6年
A16: 减：残值回收 | B16: =-'1-参数配置'!B13 | C16: 元 | D16: 6年后转卖
A17: 6年TCO总成本 | B17: =SUM(B14:B16) | C17: 元 | D17: 总拥有成本
A19: 三、单位成本
A20: 年均成本 | B20: ='2-运营商-订阅模式'!B17/'1-参数配置'!B12 | C20: 元/年 | D20: =TCO÷6年

Sheet 3-运营商-人驾轻卡
A1: 运营商视角 - 人驾电动轻卡TCO分析（7年）
A2: 💡 本Sheet所有数据自动计算，修改参数表即可更新
A4: 一、年度成本拆解
A5: 成本项 | B5: 金额 | C5: 单位 | D5: 计算说明
A6: 司机工资 | B6: ='1-参数配置'!C43 | C6: 元/年 | D6: 含社保
A7: 保险费用 | B7: ='1-参数配置'!C45 | C7: 元/年 | D7: 营运车辆险
A8: 维保成本 | B8: ='1-参数配置'!C46 | C8: 元/年 | D8: 维修保养
A9: 其他成本 | B9: ='1-参数配置'!C47 | C9: 元/年 | D9: 过路费等
A10: 年度总成本 | B10: =SUM(B6:B9) | C10: 元/年 | D10: 运营成本合计
A12: 二、7年总拥有成本(TCO)
A13: 车辆采购成本 | B13: ='1-参数配置'!C9 | C13: 元 | D13: 一次性投入
A14: 7年运营成本 | B14: ='3-运营商-人驾轻卡'!B10*'1-参数配置'!C12 | C14: 元 | D14: =年成本×7年
A15: 减：残值回收 | B15: =-'1-参数配置'!C13 | C15: 元 | D15: 7年后转卖
A16: 7年TCO总成本 | B16: =SUM(B13:B15) | C16: 元 | D16: 总拥有成本
A18: 三、单位成本
A19: 年均成本 | B19: ='3-运营商-人驾轻卡'!B16/'1-参数配置'!C12 | C19: 元/年 | D19: =TCO÷7年

Sheet 4-运营商对比
A1: 运营商视角 - 订阅模式 vs 人驾模式对比
A3: 核心指标对比
A4: 对比项 | B4: 订阅模式(6年) | C4: 人驾模式(7年) | D4: 优势方
A5: 生命周期TCO | B5: ='2-运营商-订阅模式'!B17 | C5: ='3-运营商-人驾轻卡'!B16 | D5: =IF(B5<C5,"订阅","人驾")
A6: 年均成本 | B6: ='2-运营商-订阅模式'!B17/6 | C6: ='3-运营商-人驾轻卡'!B16/7 | D6: =IF(B6<C6,"订阅","人驾")
A7: 初始投资 | B7: ='1-参数配置'!B9 | C7: ='1-参数配置'!C9 | D7: =IF(B7<C7,"订阅","人驾")

Sheet 5-厂商盈利分析
A1: 厂商视角 - 订阅模式 vs 一次性买断盈利分析
A2: 当前场景：销售规模 1000 台 | 安全员配比 1:20
A4: 【订阅模式 - 厂商盈利分析】 | D4: 【一次性买断 - 厂商盈利分析】
A5: 单车初期成本
A6: 硬件BOM | B6: ='1-参数配置'!B58 | C6: 引用参数表
A7: 研发分摊 | B7: ='1-参数配置'!B56 | C7: 规模效应关键
A8: 生产成本 | B8: ='1-参数配置'!B59
A9: 销售费用 | B9: =79800*'1-参数配置'!B60 | C9: 收入×12%
A10: 初期成本合计 | B10: =SUM(B6:B9)
A12: 年度持续成本
A13: 监控成本 | B13: ='1-参数配置'!B70 | C13: 规模效应
A14: 软件运维 | B14: =34000*(1-'1-参数配置'!B61) | C14: 订阅费×40%
A15: 技术支持 | B15: 2000
A16: 年度成本小计 | B16: =SUM(B13:B15)
A18: 收入结构
A19: 车辆销售收入 | B19: 79800
A20: 6年软件订阅 | B20: =34000*6
A21: 6年总收入 | B21: =B19+B20
A23: 6年利润分析
A24: 总收入 | B24: =B21
A25: 初期成本 | B25: =-B10
A26: 6年持续成本 | B26: =-B16*6
A27: 6年总利润 | B27: =SUM(B24:B26)
A28: 单车净利率 | B28: =B27/B21
A30: 盈亏平衡分析
A31: 单车利润(不含研发) | B31: =B27+B7 | C31: 回推单车边际利润
A32: 盈亏平衡台数 | B32: ='1-参数配置'!B55/B31 | C32: 需卖多少台盈利

Sheet 6-综合对比
A1: 双视角综合对比 - 运营商 & 厂商
A3: 运营商视角：订阅模式6年TCO更优
A5: 厂商视角：订阅模式更易盈亏平衡
A7: 💡 调整Sheet 1的"销售规模"和"安全员配比"参数可观察规模效应
